Workbook
Name PROGRESO_HU: _xlfn.LAMBDA(IF(COUNTIF('Sprint 3 Backlog'!$C$2:$E$2,TRUE)=0,"Pendiente",IF(COUNTIF('Sprint 3 Backlog'!$C$2:$E$2,TRUE)=3,"Completado","En curso")))

Sheet Sprint 3 Backlog
A1: ID HUs | B1: Título | C1: C1 | D1: C2 | E1: C3 | F1: SP | G1: Tiempo Real Invertido (Hrs) | H1: Estado | I1: Responsable | J1: Fecha Inicio | K1: Fecha Fin
A2: =IFERROR(__xludf.DUMMYFUNCTION("FILTER({'Listado de HUs'!A2:A23; 'Requisitos No Funcionales'!A2:A23}, {LEN('Listado de HUs'!A2:A23); LEN('Requisitos No Funcionales'!A2:A23)}) "),1) -> 1 | B2: Diagnosis and Severity Management | C2: TRUE | D2: TRUE | E2: TRUE | F2: {=IF(ISBLANK(A2:A23),"",IFERROR(VLOOKUP(A2:A23,'Requisitos No Funcionales'!A:A,1,FALSE)*0,IFERROR(VLOOKUP(A2:A23,'Listado de HUs'!A:C,3,FALSE),0)))} -> 6 | G2: {=IF(A2:A23="","",SUMIF('Registro de Horas Trabajadas'!A:A,A2:A23,'Registro de Horas Trabajadas'!D:D))} -> 1 | H2: =IF(COUNTIF(C2:E2,TRUE)=0,"Pendiente",IF(COUNTIF(C2:E2,TRUE)=3,"Completado","En curso")) -> Completado | I2: Antonio, Pancho | J2: 45960 | K2: 45963
A3: =IFERROR(__xludf.DUMMYFUNCTION("""COMPUTED_VALUE"""),2) -> 2 | B3: Medical Prescription Update | C3: TRUE | D3: TRUE | E3: TRUE | F3: 8 | G3: 11 | H3: =IF(COUNTIF(C3:E3,TRUE)=0,"Pendiente",IF(COUNTIF(C3:E3,TRUE)=3,"Completado","En curso")) -> Completado | I3: Antonio, Felipe | J3: 45961 | K3: 45964
A4: =IFERROR(__xludf.DUMMYFUNCTION("""COMPUTED_VALUE"""),3) -> 3 | B4: Patient Safety Plan Edition | C4: TRUE | D4: TRUE | E4: TRUE | F4: 7 | G4: 15 | H4: =IF(COUNTIF(C4:E4,TRUE)=0,"Pendiente",IF(COUNTIF(C4:E4,TRUE)=3,"Completado","En curso")) -> Completado | I4: Byron, Pancho | J4: 45955 | K4: 45956
A5: =IFERROR(__xludf.DUMMYFUNCTION("""COMPUTED_VALUE"""),4) -> 4 | B5: Viewing and Exporting the Security Plan (PDF) | C5: TRUE | D5: TRUE | E5: TRUE | F5: 5 | G5: 7 | H5: =IF(COUNTIF(C5:E5,TRUE)=0,"Pendiente",IF(COUNTIF(C5:E5,TRUE)=3,"Completado","En curso")) -> Completado | I5: Antonio, Felipe | J5: 45958
A6: =IFERROR(__xludf.DUMMYFUNCTION("""COMPUTED_VALUE"""),5) -> 5 | B6: Security Plan Update Notification | C6: TRUE | D6: TRUE | E6: TRUE | F6: 3 | G6: 7 | H6: =IF(COUNTIF(C6:E6,TRUE)=0,"Pendiente",IF(COUNTIF(C6:E6,TRUE)=3,"Completado","En curso")) -> Completado | I6: Antonio, Felipe | J6: 45965 | K6: 45966
A7: =IFERROR(__xludf.DUMMYFUNCTION("""COMPUTED_VALUE"""),6) -> 6 | B7: Onboarding Guide for New Users | C7: TRUE | D7: TRUE | E7: TRUE | F7: 5 | G7: 9 | H7: =IF(COUNTIF(C7:E7,TRUE)=0,"Pendiente",IF(COUNTIF(C7:E7,TRUE)=3,"Completado","En curso")) -> Completado | I7: Byron, Felipe | J7: 45962
A8: =IFERROR(__xludf.DUMMYFUNCTION("""COMPUTED_VALUE"""),7) -> 7 | B8: Questionnaire history | C8: TRUE | D8: TRUE | E8: TRUE | F8: 3 | G8: 5 | H8: =IF(COUNTIF(C8:E8,TRUE)=0,"Pendiente",IF(COUNTIF(C8:E8,TRUE)=3,"Completado","En curso")) -> Completado | I8: Byron, Felipe | J8: 45957 | K8: 45958
A9: =IFERROR(__xludf.DUMMYFUNCTION("""COMPUTED_VALUE"""),8) -> 8 | B9: Psychiatrist Calendar | C9: TRUE | D9: TRUE | E9: TRUE | F9: 6 | G9: 10 | H9: =IF(COUNTIF(C9:E9,TRUE)=0,"Pendiente",IF(COUNTIF(C9:E9,TRUE)=3,"Completado","En curso")) -> Completado | I9: Antonio | J9: 45957 | K9: 45958
A10: =IFERROR(__xludf.DUMMYFUNCTION("""COMPUTED_VALUE"""),9) -> 9 | B10: Central Alert Indicator | C10: TRUE | D10: TRUE | E10: TRUE | F10: 4 | G10: 1 | H10: =IF(COUNTIF(C10:E10,TRUE)=0,"Pendiente",IF(COUNTIF(C10:E10,TRUE)=3,"Completado","En curso")) -> Completado | I10: Pancho | J10: 45957 | K10: 45957
A11: =IFERROR(__xludf.DUMMYFUNCTION("""COMPUTED_VALUE"""),10) -> 10 | B11: Detailed Alert Display | C11: TRUE | D11: TRUE | E11: TRUE | F11: 4 | G11: 4 | H11: =IF(COUNTIF(C11:E11,TRUE)=0,"Pendiente",IF(COUNTIF(C11:E11,TRUE)=3,"Completado","En curso")) -> Completado | I11: Pancho, Antonio | J11: 45958 | K11: 45960
A12: =IFERROR(__xludf.DUMMYFUNCTION("""COMPUTED_VALUE"""),11) -> 11 | B12: Visual Clue of New Content | C12: TRUE | D12: TRUE | E12: TRUE | F12: 3 | G12: 4.1 | H12: =IF(COUNTIF(C12:E12,TRUE)=0,"Pendiente",IF(COUNTIF(C12:E12,TRUE)=3,"Completado","En curso")) -> Completado | I12: Pancho | J12: 45964 | K12: 45965
A13: =IFERROR(__xludf.DUMMYFUNCTION("""COMPUTED_VALUE"""),12) -> 12 | B13: Personalization of Daily Tips | C13: TRUE | D13: TRUE | E13: TRUE | F13: 2 | G13: 3 | H13: =IF(COUNTIF(C13:E13,TRUE)=0,"Pendiente",IF(COUNTIF(C13:E13,TRUE)=3,"Completado","En curso")) -> Completado | I13: Byron | J13: 45955 | K13: 45955
A14: =IFERROR(__xludf.DUMMYFUNCTION("""COMPUTED_VALUE"""),13) -> 13 | B14: Psychiatrist Details Page | C14: TRUE | D14: TRUE | E14: TRUE | F14: 8 | G14: 9 | H14: =IF(COUNTIF(C14:E14,TRUE)=0,"Pendiente",IF(COUNTIF(C14:E14,TRUE)=3,"Completado","En curso")) -> Completado | I14: Pancho, Antonio | J14: 45956 | K14: 45959
A15: =IFERROR(__xludf.DUMMYFUNCTION("""COMPUTED_VALUE"""),801) -> 801 | B15: Database Structure and Normalization | C15: TRUE | D15: TRUE | E15: TRUE | F15: 0 | G15: 4 | H15: =IF(COUNTIF(C15:E15,TRUE)=0,"Pendiente",IF(COUNTIF(C15:E15,TRUE)=3,"Completado","En curso")) -> Completado | I15: Antonio
A16: =IFERROR(__xludf.DUMMYFUNCTION("""COMPUTED_VALUE"""),802) -> 802 | B16: Interface Agility | C16: TRUE | D16: TRUE | E16: FALSE | F16: 0 | G16: 0 | H16: =IF(COUNTIF(C16:E16,TRUE)=0,"Pendiente",IF(COUNTIF(C16:E16,TRUE)=3,"Completado","En curso")) -> En curso | I16: Kaiso, Pancho
A17: =IFERROR(__xludf.DUMMYFUNCTION("""COMPUTED_VALUE"""),803) -> 803 | B17: Mobile Login Mechanism | C17: TRUE | D17: FALSE | E17: FALSE | F17: 0 | G17: 0 | H17: =IF(COUNTIF(C17:E17,TRUE)=0,"Pendiente",IF(COUNTIF(C17:E17,TRUE)=3,"Completado","En curso")) -> En curso
A18: =IFERROR(__xludf.DUMMYFUNCTION("""COMPUTED_VALUE"""),804) -> 804 | B18: Mobile Interface Coherence | C18: TRUE | D18: TRUE | E18: FALSE | F18: 0 | G18: 1 | H18: =IF(COUNTIF(C18:E18,TRUE)=0,"Pendiente",IF(COUNTIF(C18:E18,TRUE)=3,"Completado","En curso")) -> En curso | I18: Byron, Kaiso, Pancho | J18: 45964 | K18: 45964
A19: =IFERROR(__xludf.DUMMYFUNCTION("""COMPUTED_VALUE"""),805) -> 805 | B19: Change history | C19: TRUE | D19: TRUE | E19: TRUE | F19: 0 | G19: 1 | H19: =IF(COUNTIF(C19:E19,TRUE)=0,"Pendiente",IF(COUNTIF(C19:E19,TRUE)=3,"Completado","En curso")) -> Completado
A20: =IFERROR(__xludf.DUMMYFUNCTION("""COMPUTED_VALUE"""),806) -> 806 | B20: Interface Visualization | C20: TRUE | D20: FALSE | E20: FALSE | F20: 0 | G20: 0 | H20: =IF(COUNTIF(C20:E20,TRUE)=0,"Pendiente",IF(COUNTIF(C20:E20,TRUE)=3,"Completado","En curso")) -> En curso | I20: Pancho, Kaiso | J20: 45963 | K20: 45964
A21: =IFERROR(__xludf.DUMMYFUNCTION("""COMPUTED_VALUE"""),807) -> 807 | B21: Data validation | C21: TRUE | D21: TRUE | E21: FALSE | F21: 0 | G21: 0 | H21: =IF(COUNTIF(C21:E21,TRUE)=0,"Pendiente",IF(COUNTIF(C21:E21,TRUE)=3,"Completado","En curso")) -> En curso | I21: Felipe | J21: 45964 | K21: 45964
A22: =IFERROR(__xludf.DUMMYFUNCTION("""COMPUTED_VALUE"""),808) -> 808 | B22: DB alerts | C22: TRUE | D22: TRUE | E22: TRUE | F22: 0 | G22: 0 | H22: =IF(COUNTIF(C22:E22,TRUE)=0,"Pendiente",IF(COUNTIF(C22:E22,TRUE)=3,"Completado","En curso")) -> Completado | I22: Antonio, Felipe
A23: =IFERROR(__xludf.DUMMYFUNCTION("""COMPUTED_VALUE"""),809) -> 809 | B23: new alerts | C23: TRUE | D23: FALSE | E23: FALSE | F23: 0 | G23: 0 | H23: =IF(COUNTIF(C23:E23,TRUE)=0,"Pendiente",IF(COUNTIF(C23:E23,TRUE)=3,"Completado","En curso")) -> En curso | I23: Antonio | J23: 45962 | K23: 45962

Sheet Listado de HUs
A1: ID HU | B1: Título | C1: SP | D1: Historia de Usuario | E1: Criterios de Aceptación | F1: Criterio de Aceptación 1 | G1: Criterio de Aceptación 2 | H1: Criterio de Aceptación 3
A2: =ROW()-1 -> 1 | B2: Diagnosis and Severity Management | C2: 6 | D2: As a psychiatrist, I want to be able to edit my patient's clinical diagnosis and assign a severity level to maintain accurate and up-to-date control of their mental health status. | E2: ="1. "&F2&CHAR(10)&"2. "&G2&CHAR(10)&"3. "&H2 -> 1. Since the psychiatrist is in the "Patient View", when you select a patient and access the "Diagnosis" section, you can then edit the existing diagnosis and save the changes. 2. Since the psychiatrist edits the diagnosis, they can then select and save a "Severity Level" associated with that diagnosis (e.g., Mild, Moderate, Severe). 3. Since an edit is made and the changes to the diagnosis or severity are saved, the system automatically records the date, time, the user who made the modification, and the previous value of the diagnosis in an immutable patient history. | F2: Since the psychiatrist is in the "Patient View", when you select a patient and access the "Diagnosis" section, you can then edit the existing diagnosis and save the changes. | G2: Since the psychiatrist edits the diagnosis, they can then select and save a "Severity Level" associated with that diagnosis (e.g., Mild, Moderate, Severe). | H2: Since an edit is made and the changes to the diagnosis or severity are saved, the system automatically records the date, time, the user who made the modification, and the previous value of the diagnosis in an immutable patient history.
A3: =ROW()-1 -> 2 | B3: Medical Prescription Update | C3: 8 | D3: As a psychiatrist, I want to be able to see my patient's current medication and enter a new one or modify the prescription to ensure that the drug treatment is appropriate at all times. | E3: ="1. "&F3&CHAR(10)&"2. "&G3&CHAR(10)&"3. "&H3 -> 1. Since the psychiatrist is in the "Patient View", when he accesses the "Medications" section, he can clearly see the medication currently prescribed by the patient. 2. Since the psychiatrist accesses the "Medications" section, they can then add a new medication or modify an existing one, and the system saves and displays the new prescription as current. 3. Since the psychiatrist adds or modifies a prescription, the system automatically records the date, time, the user who performed the action, the previous medication, and the new medication in the patient's treatment history. | F3: Since the psychiatrist is in the "Patient View", when he accesses the "Medications" section, he can clearly see the medication currently prescribed by the patient. | G3: Since the psychiatrist accesses the "Medications" section, they can then add a new medication or modify an existing one, and the system saves and displays the new prescription as current. | H3: Since the psychiatrist adds or modifies a prescription, the system automatically records the date, time, the user who performed the action, the previous medication, and the new medication in the patient's treatment history.
A4: =ROW()-1 -> 3 | B4: Patient Safety Plan Edition | C4: 7 | D4: As a patient, I want to be able to edit my safety plan at any time to ensure I have an up-to-date and relevant action plan for when I feel in crisis or unwell. | E4: ="1. "&F4&CHAR(10)&"2. "&G4&CHAR(10)&"3. "&H4 -> 1. Given an authenticated patient, when they access the "Security Plan View", they can then modify any of the plan fields and successfully save the changes. 2. Since the patient edits and saves their Safety Plan, the system automatically records the date, time, and an indicator that the plan was updated by the patient, maintaining a history of previous versions. 3. Given a patient who edits their safety plan, they can add an emergency number which can be used to call them by tapping the number in the plan view. | F4: Given an authenticated patient, when they access the "Security Plan View", they can then modify any of the plan fields and successfully save the changes. | G4: Since the patient edits and saves their Safety Plan, the system automatically records the date, time, and an indicator that the plan was updated by the patient, maintaining a history of previous versions. | H4: Given a patient who edits their safety plan, they can add an emergency number which can be used to call them by tapping the number in the plan view.
A5: =ROW()-1 -> 4 | B5: Viewing and Exporting the Security Plan (PDF) | C5: 5 | D5: As a psychiatrist, I want to be able to view my patient's safety plan and export it in PDF format to have a backup copy and reference of my patient's coping strategy. | E5: ="1. "&F5&CHAR(10)&"2. "&G5&CHAR(10)&"3. "&H5 -> 1. Given a psychiatrist, when viewing a patient's safety plan, they can then select the "Export to PDF" option and the document is downloaded with the full content of the plan. 2. Since the psychiatrist exports the plan to PDF, the generated document maintains the readable formatting and design of the web view. 3. Since the PDF is generated, it includes information such as the patient's name, the date of the last plan update, and the export date. | F5: Given a psychiatrist, when viewing a patient's safety plan, they can then select the "Export to PDF" option and the document is downloaded with the full content of the plan. | G5: Since the psychiatrist exports the plan to PDF, the generated document maintains the readable formatting and design of the web view. | H5: Since the PDF is generated, it includes information such as the patient's name, the date of the last plan update, and the export date.
A6: =ROW()-1 -> 5 | B6: Security Plan Update Notification | C6: 3 | D6: As a psychiatrist, I want to see a visual cue if my patient has recently updated their safety plan so I know when to review the changes and discuss it in our next session. | E6: ="1. "&F6&CHAR(10)&"2. "&G6&CHAR(10)&"3. "&H6 -> 1. Since the patient has edited and saved their Safety Plan, when the psychiatrist accesses the "Patient View", a clear visual indicator (e.g., a "New" or "Updated" icon) is displayed next to the patient's name or their safety plan. 2. Given an updated safety plan notification, when the psychiatrist accesses the view, he can review what data has changed from the previous one. 3. Given an updated security plan, when the psychiatrist closes the view of the changes made, the visual cue will disappear. | F6: Since the patient has edited and saved their Safety Plan, when the psychiatrist accesses the "Patient View", a clear visual indicator (e.g., a "New" or "Updated" icon) is displayed next to the patient's name or their safety plan. | G6: Given an updated safety plan notification, when the psychiatrist accesses the view, he can review what data has changed from the previous one. | H6: Given an updated security plan, when the psychiatrist closes the view of the changes made, the visual cue will disappear.
A7: =ROW()-1 -> 6 | B7: Onboarding Guide for New Users | C7: 5 | D7: As a new user, I want a simple and guided onboarding process the first time I use the app so I can easily and quickly understand how to use the main features of the application. | E7: ="1. "&F7&CHAR(10)&"2. "&G7&CHAR(10)&"3. "&H7 -> 1. Since the user starts the application for the first time, when they log in, a sequence of no more than 4 screens is presented that explain the key functionalities of the app. 2. Since the user is in the onboarding process, they have the clear option to "Skip" or "Leave out" the process at any time. 3. Since the user has completed or skipped the onboarding process, when they log back in, the onboarding process is not displayed again. | F7: Since the user starts the application for the first time, when they log in, a sequence of no more than 4 screens is presented that explain the key functionalities of the app. | G7: Since the user is in the onboarding process, they have the clear option to "Skip" or "Leave out" the process at any time. | H7: Since the user has completed or skipped the onboarding process, when they log back in, the onboarding process is not displayed again.
A8: =ROW()-1 -> 7 | B8: Questionnaire history | C8: 3 | D8: As a patient, I want to see the responses to the forms I have filled out so I can have my answers whenever I deem it convenient. | E8: ="1. "&F8&CHAR(10)&"2. "&G8&CHAR(10)&"3. "&H8 -> 1. Given a patient in the questionnaires view, they can navigate to a view that contains a list of answered questionnaires. 2. Given a patient in the view of answered questionnaires, they can select one from the list and the responses of the selected questionnaire will be displayed. 3. Given a patient who has selected a questionnaire, they can export their responses to a PDF document. | F8: Given a patient in the questionnaires view, they can navigate to a view that contains a list of answered questionnaires. | G8: Given a patient in the view of answered questionnaires, they can select one from the list and the responses of the selected questionnaire will be displayed. | H8: Given a patient who has selected a questionnaire, they can export their responses to a PDF document.
A9: =ROW()-1 -> 8 | B9: Psychiatrist Calendar | C9: 6 | D9: As a psychiatrist, I want to have access to a personal calendar where I can add and view personal reminders. | E9: ="1. "&F9&CHAR(10)&"2. "&G9&CHAR(10)&"3. "&H9 -> 1. Given a psychiatrist, they can view a calendar in their psychiatrist details tab. 2. Given a psychiatrist, they can enter personal reminders into the calendar. 3. Given a psychiatrist, they can edit and/or delete your previously entered calendar reminders. | F9: Given a psychiatrist, they can view a calendar in their psychiatrist details tab. | G9: Given a psychiatrist, they can enter personal reminders into the calendar. | H9: Given a psychiatrist, they can edit and/or delete your previously entered calendar reminders.
A10: =ROW()-1 -> 9 | B10: Central Alert Indicator | C10: 4 | D10: As a psychiatrist, I want to have a centralized notifications icon in the app header that shows me the count of deviations or critical alerts (e.g., questionnaire responses) generated by my patients. | E10: ="1. "&F10&CHAR(10)&"2. "&G10&CHAR(10)&"3. "&H10 -> 1. Given a psychiatrist in any view, you may then see a bell icon or similar in the top navigation bar that displays a numerical counter with the total number of active, unreviewed alerts. 2. Since there are new alerts or deviations, when the psychiatrist clicks on the notifications icon, a summary list of patients and the type of alert is displayed (e.g., "Patient X - Critical Questionnaire"). 3. Since the psychiatrist clicks on an item in the drop-down list, he is then automatically redirected to the patient's record with the active alert (HU 11) and the counter is updated. | F10: Given a psychiatrist in any view, you may then see a bell icon or similar in the top navigation bar that displays a numerical counter with the total number of active, unreviewed alerts. | G10: Since there are new alerts or deviations, when the psychiatrist clicks on the notifications icon, a summary list of patients and the type of alert is displayed (e.g., "Patient X - Critical Questionnaire"). | H10: Since the psychiatrist clicks on an item in the drop-down list, he is then automatically redirected to the patient's record with the active alert (HU 11) and the counter is updated.
A11: =ROW()-1 -> 10 | B11: Visualización Detallada de Alertas | C11: 4 | D11: As a psychiatrist, I want a visible alert banner to be displayed when accessing the patient's record, detailing the deviation or active alert, so that the situation is known without having to navigate to another section. | E11: ="1. "&F11&CHAR(10)&"2. "&G11&CHAR(10)&"3. "&H11 -> 1. Given a psychiatrist who accesses a patient's record with an active alert, then a banner of a prominent color (e.g., red or orange) is displayed at the top of the record view. 2. Given the alert banner, it then contains a concise message summarizing the reason for the alert (e.g., "Depression score at Severe level") and a direct link to the source of the data (e.g., the completed questionnaire). 3. Since the psychiatrist has reviewed and marked the alert as "Resolved" or "Reviewed" in the patient's record, the alert banner is hidden and the notification counter (HU 10) is reduced. | F11: Given a psychiatrist who accesses a patient's record with an active alert, then a banner of a prominent color (e.g., red or orange) is displayed at the top of the record view. | G11: Given the alert banner, it then contains a concise message summarizing the reason for the alert (e.g., "Depression score at Severe level") and a direct link to the source of the data (e.g., the completed questionnaire). | H11: Since the psychiatrist has reviewed and marked the alert as "Resolved" or "Reviewed" in the patient's record, the alert banner is hidden and the notification counter (HU 10) is reduced.
A12: =ROW()-1 -> 11 | B12: Visual Clue of New Content | C12: 3 | D12: As a psychiatrist, I want a subtle visual cue (e.g., a blue dot) displayed next to the patient's name on the patient list if they have entered a new Emotional Diary or Questionnaire since my last review. | E12: ="1. "&F12&CHAR(10)&"2. "&G12&CHAR(10)&"3. "&H12 -> 1. Given a patient who has completed a new questionnaire or emotional diary, when the psychiatrist accesses the "Patient View", then a small visual indicator (e.g., a blue dot) appears next to the patient's name in the list. 2. Since the psychiatrist clicks on the patient with the visual cue, and accesses the section where the new content is located (e.g., Questionnaire History), then the indicator disappears when the view loads. 3. Since the psychiatrist navigates to the patient's file, the visual cue should remain visible in the patient list until they have actually reviewed the "Emotional Diary" or "Questionnaires" section. | F12: Given a patient who has completed a new questionnaire or emotional diary, when the psychiatrist accesses the "Patient View", then a small visual indicator (e.g., a blue dot) appears next to the patient's name in the list. | G12: Since the psychiatrist clicks on the patient with the visual cue, and accesses the section where the new content is located (e.g., Questionnaire History), then the indicator disappears when the view loads. | H12: Since the psychiatrist navigates to the patient's file, the visual cue should remain visible in the patient list until they have actually reviewed the "Emotional Diary" or "Questionnaires" section.
A13: =ROW()-1 -> 12 | B13: Personalization of Daily Tips | C13: 2 | D13: As a user, I want to be able to disable the display of daily tips or messages through the settings section to control the content I receive. | E13: ="1. "&F13&CHAR(10)&"2. "&G13&CHAR(10)&"3. "&H13 -> 1. Given a user, when they access the "Application Settings" section, they will find a clear option labeled "Show Daily Tips". 2. Since the user disables the "Show Daily Tips" option and saves the settings, the tips stop appearing on the home screen or in the designated section. 3. Since the user has disabled the feature, then by re-enabling the option in the settings, the daily tips will be displayed again in the application. | F13: Given a user, when they access the "Application Settings" section, they will find a clear option labeled "Show Daily Tips". | G13: Since the user disables the "Show Daily Tips" option and saves the settings, the tips stop appearing on the home screen or in the designated section. | H13: Since the user has disabled the feature, then by re-enabling the option in the settings, the daily tips will be displayed again in the application.
A14: 13 | B14: Psychiatrist Details Page | C14: 8 | D14: As a psychiatrist, I want to be able to access a page that displays relevant content, my personal information, and that I can modify. | E14: ="1. "&F14&CHAR(10)&"2. "&G14&CHAR(10)&"3. "&H14 -> 1. Given a psychiatrist, when he accesses it, he will be able to view your personal information along with relevant content. 2. Given a psychiatrist, that he/she may be able to edit his/her personal information in the user view. 3. Given a psychiatrist, they can choose what to view in their details, their personal information, their calendar with their reminders, among other things. | F14: Given a psychiatrist, when he accesses it, he will be able to view your personal information along with relevant content. | G14: Given a psychiatrist, that he/she may be able to edit his/her personal information in the user view. | H14: Given a psychiatrist, they can choose what to view in their details, their personal information, their calendar with their reminders, among other things.

Sheet Requisitos No Funcionales
A1: ID RNF | B1: Título | C1: Detalle | D1: COMODIN KAISO
A2: =800+ROW()-1 -> 801 | B2: Estructura y Normalización de la Base de Datos | C2: La base de datos debe ser normalizada y estructurada para asegurar la separación lógica de los datos de salud mental (diagnósticos, recetas, respuestas) y optimizar la integridad referencial y la eficiencia de las consultas. | D2: FALSE
A3: =800+ROW()-1 -> 802 | B3: Agilidad de Interfaz | C3: La interacción con la aplicación web (transiciones, desplazamiento y carga de elementos) debe ser fluida y reactiva, sin demoras visibles, manteniendo una sensación de respuesta inmediata al usuario. | D3: FALSE
A4: =800+ROW()-1 -> 803 | B4: Mecanismo de Login Móvil | C4: El proceso de autenticación en la aplicación móvil debe estar restringido a la combinación de Correo Electrónico y Contraseña. | D4: FALSE
A5: =800+ROW()-1 -> 804 | B5: Coherencia de Interfaz Móvil | C5: La interfaz de usuario en la aplicación móvil debe ser desarrollada siguiendo rigurosamente las guías de diseño establecidas (p. ej., por el equipo de diseño) para garantizar la coherencia y una experiencia de usuario optimizada para el tacto. | D5: FALSE
A6: =800+ROW()-1 -> 805 | B6: Historial de cambios | C6: El historial de cambios (diagnóstico, receta, plan de seguridad) debe ser inmutable (append-only) para garantizar la integridad y la auditoría de los datos. | D6: FALSE
A7: =800+ROW()-1 -> 806 | B7: Visualización de la Interfaz | C7: La interfaz de usuario debe ser intuitiva y consistente en todas las secciones, utilizando los mismos patrones de diseño y nomenclatura para acciones similares (ej. "Guardar", "Editar"). | D7: FALSE
A8: =800+ROW()-1 -> 807 | B8: Validación de datos | C8: Todo campo de entrada crítico debe incluir validación de datos en el lado del cliente y del servidor, mostrando mensajes de error claros y accionables al usuario. | D8: FALSE
A9: =800+ROW()-1 -> 808 | B9: BD alertas | C9: Configurar tabla alertas (desvios y plan seguro) en BD para poder actualizar correctamente la HU9 y 10 | D9: FALSE
A10: =800+ROW()-1 -> 809 | B10: nuevas alertas | C10: Agregar alertas de cuestionarios y plan seguro | D10: FALSE

Sheet Registro de Horas Trabajadas
A1: ID HUs | B1: Persona | C1: Fecha | D1: Horas Invertidas | E1: Nota
A2: 12 | B2: Byron | C2: 45955 | D2: 3 | E2: Hay que modificar visualmente el frame cuando no esten los consejos ya que se ve un poco raro
A3: 3 | B3: Byron | C3: 45955 | D3: 4 | E3: Modifiqué Plan Seguro de modo que ahora es una coleccion de Consejos, He creado el viewmodel del planseguro, ademas la nueva vista de edicion.
A4: Smartwatch | B4: Byron | C4: 45956 | D4: 3 | E4: Prueba adaptacion de healthconnect basado en este: https://github.com/EagleDelux/androidx.health-connect-demo-.net-maui
A5: Marketing | B5: Kaiso | C5: 45956 | D5: 1 | E5: Diseño y Programación de Post Linkedlin
A6: Marketing | B6: Kaiso | C6: 45956 | D6: 2 | E6: Diseño y Edición Post Instagram
A7: 9 | B7: Pancho | C7: 45957 | D7: 1 | E7: HU 9 completa
A8: 7 | B8: Byron | C8: 45957 | D8: 2 | E8: Criterio 1 completado.
A9: 7 | B9: Byron | C9: 45958 | D9: 3 | E9: Criterio 2 y 3 completados, falta ponerle color con la vista jeje
A10: 3 | B10: Byron | C10: 45958 | D10: 3 | E10: criterio 1 y 3 en curso
A11: Marketing | B11: Kaiso | C11: 45958 | D11: 5 | E11: Investigación, redacción y revisión del artículo para Linkedlin
A12: 10 | B12: Pancho | C12: 45958 | D12: 2 | E12: HU 10 casi completa y BD actualizada
A13: 13 | B13: Antonio | C13: 45958 | D13: 7 | E13: Creación vista detalles psiquiatra C1 y C3 cumplido
A14: 8 | B14: Antonio | C14: 45958 | D14: 5 | E14: Creación controllers y tablas relacionadas a calendario del psiquiatra, C1 cumplido.
A15: 801 | B15: Antonio | C15: 45958 | D15: 3 | E15: Creación tablas Logs, RecordatoriosPsiquiatra y modificación tabla Pacientes, UsuariosExternos.
A16: 13 | B16: Antonio | C16: 45959 | D16: 2 | E16: Vista edición de datos personales del psiquiatra, modificación método de edición. C2 completado.
A17: 8 | B17: Antonio | C17: 45959 | D17: 5 | E17: Ingreso, Edición, Eliminación de recordatorios implementado, colores a recordatorios personalizables, vista de agenda semanal por horas. C2 Y C3 completados.
A18: 801 | B18: Antonio | C18: 45959 | D18: 1 | E18: Modificaciones a tablas, columna de PlanSeguro en Paciente, Color y IsAllDay en tabla RecordatoriosPsiquiatra.
A19: Marketing | B19: Pancho | C19: 45959 | D19: 3 | E19: Mejora visual de la página del producto
A20: 10 | B20: Pancho | C20: 45960 | D20: 2 | E20: Reintegrar algoritmo de alertas y Severidad en Pacientes
A21: Smartwatch | B21: Byron | C21: 45960 | D21: 3 | E21: Pruebas en Adaptacion de app health utilizada como prueba de concepto,probamos carga de datos en celular
A22: Smartwatch | B22: Byron | C22: 45961 | D22: 5 | E22: Integracion de app Health en MoodTAB, Se agregó en la vista HealthData. falta realizar pruebas con datos de smartwatch, el lunes me consigo uno jeje.
A23: 6 | B23: Byron | C23: 45962 | D23: 2 | E23: Implementacion base de tutorial en movil
A24: 804 | B24: Byron | C24: 45963 | D24: 1 | E24: login movil
A25: 1 | B25: Pancho | C25: 45963 | D25: 1 | E25: HU1
A26: Marketing | B26: Kaiso | C26: 45963 | D26: 2 | E26: Preparación de Post Linkedlin
B27: Pancho | C27: 45963 | D27: 2 | E27: Implementación LOGS al crear Diario emocional
A28: 2 | B28: Antonio | C28: 45963 | D28: 10 | E28: HU2 Completa
A29: 2 | B29: Antonio | C29: 45963 | D29: 1 | E29: Modificación a Paciente/Details.cshtml para arreglar error de lectura de array vacío
A30: 6 | B30: Byron | C30: 45964 | D30: 3 | E30: Modificacion tutorial inicial y creacion de tutorial para diario.
A31: Marketing | B31: Kaiso | C31: 45964 | D31: 4 | E31: Post de Linkedlin, revision de estudio citado y preparación instagram
A32: 11 | B32: Pancho | C32: 45964 | D32: 4 | E32: HU11y pulido de logs
A33: 3 | B33: Byron | C33: 45964 | D33: 4 | E33: H3 Modificacion completa del modelo de datos.
A34: Testing | B34: Kaiso | C34: 45965 | D34: 3 | E34: Generación de Informe correcciones Testing
A35: 3 | B35: Byron | C35: 45965 | D35: 4 | E35: Ahora si planseguro se guarda en la bd, se genera un log con la fecha y hora de modificacion
A36: 805 | B36: Byron | C36: 45965 | D36: 1 | E36: logs de plan seguro y update datos paciente.
A37: Testing | B37: Kaiso | C37: 45960 | D37: 1.5 | E37: Pruebas de UI Web
A38: Testing | B38: Pancho | C38: 45960 | D38: 1.5 | E38: Pruebas de UI Web
A39: Testing | B39: Kaiso | C39: 45965 | D39: 1.5 | E39: Pruebas de UI Movil
A40: Testing | B40: Pancho | C40: 45965 | D40: 1.5 | E40: Pruebas de UI Movil
...

Sheet Comentarios HUs
A1: ID HUs | B1: Persona | C1: Fecha | D1: Notas y Comentarios
A2: 3 | B2: Byron | C2: 45955 | D2: Actualmente estoy modificando los consejos que agregue en el diccionario de globals
A3: 7 | B3: Byron | C3: 45957 | D3: Cree un metodo get para los cuestionarios completados. | F3: README | G3: Si te encuentras desarrollando una HU que afecta o puede afectar a otra, deja una nota para hacerle saber al resto los detalles que consideres pertinentes.
A4: 3 | B4: Byron | C4: 45965 | D4: A la mierda los consejos lo de ahora son listas de strings para un tip/consejo y listas de un obj persona/ocntacto

Sheet Registro de Incidentes
A1: ID HUs | B1: Descripción Incidentes | C1: ¿Impidió Avance? | D1: Re-Trabajo (Hrs) | E1: Bugs Encontrados
A2: NaN | B2: ME PITIEEE LA BD!!!!!!!!!!!!!!!!!!!!!!!!!!!!!!!!!!!!! | C2: TRUE | D2: 1.5 | E2: 0
A3: Smartwatch | B3: el plugin no tiene declarada la funcion getHeartRateVariabilityMillis en los registros de HRV | C3: TRUE | D3: 2 | E3: 1 | G3: README | H3: Si al estar desarrollando una HU ocurre un imprevisto remarcable que obstaculice tu progreso, reportalo aqui.

Sheet Métricas Memoria
A1: ID HUs | B1: Story Points (SP) | C1: Estimación de Horas | D1: Total Personas Asignadas | E1: Horas Reales | F1: Desviación | G1: Total Bloqueos | H1: Re-trabajo (hrs) | I1: Total Bugs Encontrados
A2: {=INDEX('Sprint 3 Backlog'!A:A,ROW(A2))} -> 1 | B2: {=IF(ISBLANK(A2:A23),"",IFERROR(VLOOKUP(A2:A23,'Requisitos No Funcionales'!A:A,1,FALSE)*0,IFERROR(VLOOKUP(A2:A23,'Listado de HUs'!A:C,3,FALSE),0)))} -> 6 | C2: =B2*6 -> 36 | D2: =IFERROR(__xludf.DUMMYFUNCTION("IFERROR(IF(VLOOKUP(A2, 'Sprint 3 Backlog'!A:I, 9, FALSE)="""", 0, COUNTA(SPLIT(VLOOKUP(A2, 'Sprint 3 Backlog'!A:I, 9, FALSE), "",""))), 0) "),2) -> 2 | E2: =IFERROR(__xludf.DUMMYFUNCTION("FILTER('Sprint 3 Backlog'!G2:G23, LEN('Sprint 3 Backlog'!G2:G23))"),1) -> 1 | F2: =E2-C2 -> -35 | G2: =COUNTIFS('Registro de Incidentes'!A:A,A2,'Registro de Incidentes'!C:C,TRUE) -> 0 | H2: =IF(COUNTIF('Registro de Incidentes'!A:A,A2)=0,0,SUMIF('Registro de Incidentes'!A:A,A2,'Registro de Incidentes'!D:D)) -> 0 | I2: =IF(COUNTIF('Registro de Incidentes'!A:A,A2)=0,0,SUMIF('Registro de Incidentes'!A:A,A2,'Registro de Incidentes'!E:E)) -> 0
A3: {=INDEX('Sprint 3 Backlog'!A:A,ROW(A3))} -> 2 | B3: 8 | C3: =B3*6 -> 48 | D3: =IFERROR(__xludf.DUMMYFUNCTION("IFERROR(IF(VLOOKUP(A3, 'Sprint 3 Backlog'!A:I, 9, FALSE)="""", 0, COUNTA(SPLIT(VLOOKUP(A3, 'Sprint 3 Backlog'!A:I, 9, FALSE), "",""))), 0) "),2) -> 2 | E3: =IFERROR(__xludf.DUMMYFUNCTION("""COMPUTED_VALUE"""),11) -> 11 | F3: =E3-C3 -> -37 | G3: =COUNTIFS('Registro de Incidentes'!A:A,A3,'Registro de Incidentes'!C:C,TRUE) -> 0 | H3: =IF(COUNTIF('Registro de Incidentes'!A:A,A3)=0,0,SUMIF('Registro de Incidentes'!A:A,A3,'Registro de Incidentes'!D:D)) -> 0 | I3: =IF(COUNTIF('Registro de Incidentes'!A:A,A3)=0,0,SUMIF('Registro de Incidentes'!A:A,A3,'Registro de Incidentes'!E:E)) -> 0
A4: {=INDEX('Sprint 3 Backlog'!A:A,ROW(A4))} -> 3 | B4: 7 | C4: =B4*6 -> 42 | D4: =IFERROR(__xludf.DUMMYFUNCTION("IFERROR(IF(VLOOKUP(A4, 'Sprint 3 Backlog'!A:I, 9, FALSE)="""", 0, COUNTA(SPLIT(VLOOKUP(A4, 'Sprint 3 Backlog'!A:I, 9, FALSE), "",""))), 0) "),2) -> 2 | E4: =IFERROR(__xludf.DUMMYFUNCTION("""COMPUTED_VALUE"""),15) -> 15 | F4: =E4-C4 -> -27 | G4: =COUNTIFS('Registro de Incidentes'!A:A,A4,'Registro de Incidentes'!C:C,TRUE) -> 0 | H4: =IF(COUNTIF('Registro de Incidentes'!A:A,A4)=0,0,SUMIF('Registro de Incidentes'!A:A,A4,'Registro de Incidentes'!D:D)) -> 0 | I4: =IF(COUNTIF('Registro de Incidentes'!A:A,A4)=0,0,SUMIF('Registro de Incidentes'!A:A,A4,'Registro de Incidentes'!E:E)) -> 0
A5: {=INDEX('Sprint 3 Backlog'!A:A,ROW(A5))} -> 4 | B5: 5 | C5: =B5*6 -> 30 | D5: =IFERROR(__xludf.DUMMYFUNCTION("IFERROR(IF(VLOOKUP(A5, 'Sprint 3 Backlog'!A:I, 9, FALSE)="""", 0, COUNTA(SPLIT(VLOOKUP(A5, 'Sprint 3 Backlog'!A:I, 9, FALSE), "",""))), 0) "),2) -> 2 | E5: =IFERROR(__xludf.DUMMYFUNCTION("""COMPUTED_VALUE"""),7) -> 7 | F5: =E5-C5 -> -23 | G5: =COUNTIFS('Registro de Incidentes'!A:A,A5,'Registro de Incidentes'!C:C,TRUE) -> 0 | H5: =IF(COUNTIF('Registro de Incidentes'!A:A,A5)=0,0,SUMIF('Registro de Incidentes'!A:A,A5,'Registro de Incidentes'!D:D)) -> 0 | I5: =IF(COUNTIF('Registro de Incidentes'!A:A,A5)=0,0,SUMIF('Registro de Incidentes'!A:A,A5,'Registro de Incidentes'!E:E)) -> 0
A6: {=INDEX('Sprint 3 Backlog'!A:A,ROW(A6))} -> 5 | B6: 3 | C6: =B6*6 -> 18 | D6: =IFERROR(__xludf.DUMMYFUNCTION("IFERROR(IF(VLOOKUP(A6, 'Sprint 3 Backlog'!A:I, 9, FALSE)="""", 0, COUNTA(SPLIT(VLOOKUP(A6, 'Sprint 3 Backlog'!A:I, 9, FALSE), "",""))), 0) "),2) -> 2 | E6: =IFERROR(__xludf.DUMMYFUNCTION("""COMPUTED_VALUE"""),7) -> 7 | F6: =E6-C6 -> -11 | G6: =COUNTIFS('Registro de Incidentes'!A:A,A6,'Registro de Incidentes'!C:C,TRUE) -> 0 | H6: =IF(COUNTIF('Registro de Incidentes'!A:A,A6)=0,0,SUMIF('Registro de Incidentes'!A:A,A6,'Registro de Incidentes'!D:D)) -> 0 | I6: =IF(COUNTIF('Registro de Incidentes'!A:A,A6)=0,0,SUMIF('Registro de Incidentes'!A:A,A6,'Registro de Incidentes'!E:E)) -> 0
A7: {=INDEX('Sprint 3 Backlog'!A:A,ROW(A7))} -> 6 | B7: 5 | C7: =B7*6 -> 30 | D7: =IFERROR(__xludf.DUMMYFUNCTION("IFERROR(IF(VLOOKUP(A7, 'Sprint 3 Backlog'!A:I, 9, FALSE)="""", 0, COUNTA(SPLIT(VLOOKUP(A7, 'Sprint 3 Backlog'!A:I, 9, FALSE), "",""))), 0) "),2) -> 2 | E7: =IFERROR(__xludf.DUMMYFUNCTION("""COMPUTED_VALUE"""),9) -> 9 | F7: =E7-C7 -> -21 | G7: =COUNTIFS('Registro de Incidentes'!A:A,A7,'Registro de Incidentes'!C:C,TRUE) -> 0 | H7: =IF(COUNTIF('Registro de Incidentes'!A:A,A7)=0,0,SUMIF('Registro de Incidentes'!A:A,A7,'Registro de Incidentes'!D:D)) -> 0 | I7: =IF(COUNTIF('Registro de Incidentes'!A:A,A7)=0,0,SUMIF('Registro de Incidentes'!A:A,A7,'Registro de Incidentes'!E:E)) -> 0
A8: {=INDEX('Sprint 3 Backlog'!A:A,ROW(A8))} -> 7 | B8: 3 | C8: =B8*6 -> 18 | D8: =IFERROR(__xludf.DUMMYFUNCTION("IFERROR(IF(VLOOKUP(A8, 'Sprint 3 Backlog'!A:I, 9, FALSE)="""", 0, COUNTA(SPLIT(VLOOKUP(A8, 'Sprint 3 Backlog'!A:I, 9, FALSE), "",""))), 0) "),2) -> 2 | E8: =IFERROR(__xludf.DUMMYFUNCTION("""COMPUTED_VALUE"""),5) -> 5 | F8: =E8-C8 -> -13 | G8: =COUNTIFS('Registro de Incidentes'!A:A,A8,'Registro de Incidentes'!C:C,TRUE) -> 0 | H8: =IF(COUNTIF('Registro de Incidentes'!A:A,A8)=0,0,SUMIF('Registro de Incidentes'!A:A,A8,'Registro de Incidentes'!D:D)) -> 0 | I8: =IF(COUNTIF('Registro de Incidentes'!A:A,A8)=0,0,SUMIF('Registro de Incidentes'!A:A,A8,'Registro de Incidentes'!E:E)) -> 0
A9: {=INDEX('Sprint 3 Backlog'!A:A,ROW(A9))} -> 8 | B9: 6 | C9: =B9*6 -> 36 | D9: =IFERROR(__xludf.DUMMYFUNCTION("IFERROR(IF(VLOOKUP(A9, 'Sprint 3 Backlog'!A:I, 9, FALSE)="""", 0, COUNTA(SPLIT(VLOOKUP(A9, 'Sprint 3 Backlog'!A:I, 9, FALSE), "",""))), 0) "),1) -> 1 | E9: =IFERROR(__xludf.DUMMYFUNCTION("""COMPUTED_VALUE"""),10) -> 10 | F9: =E9-C9 -> -26 | G9: =COUNTIFS('Registro de Incidentes'!A:A,A9,'Registro de Incidentes'!C:C,TRUE) -> 0 | H9: =IF(COUNTIF('Registro de Incidentes'!A:A,A9)=0,0,SUMIF('Registro de Incidentes'!A:A,A9,'Registro de Incidentes'!D:D)) -> 0 | I9: =IF(COUNTIF('Registro de Incidentes'!A:A,A9)=0,0,SUMIF('Registro de Incidentes'!A:A,A9,'Registro de Incidentes'!E:E)) -> 0
A10: {=INDEX('Sprint 3 Backlog'!A:A,ROW(A10))} -> 9 | B10: 4 | C10: =B10*6 -> 24 | D10: =IFERROR(__xludf.DUMMYFUNCTION("IFERROR(IF(VLOOKUP(A10, 'Sprint 3 Backlog'!A:I, 9, FALSE)="""", 0, COUNTA(SPLIT(VLOOKUP(A10, 'Sprint 3 Backlog'!A:I, 9, FALSE), "",""))), 0) "),1) -> 1 | E10: =IFERROR(__xludf.DUMMYFUNCTION("""COMPUTED_VALUE"""),1) -> 1 | F10: =E10-C10 -> -23 | G10: =COUNTIFS('Registro de Incidentes'!A:A,A10,'Registro de Incidentes'!C:C,TRUE) -> 0 | H10: =IF(COUNTIF('Registro de Incidentes'!A:A,A10)=0,0,SUMIF('Registro de Incidentes'!A:A,A10,'Registro de Incidentes'!D:D)) -> 0 | I10: =IF(COUNTIF('Registro de Incidentes'!A:A,A10)=0,0,SUMIF('Registro de Incidentes'!A:A,A10,'Registro de Incidentes'!E:E)) -> 0
A11: {=INDEX('Sprint 3 Backlog'!A:A,ROW(A11))} -> 10 | B11: 4 | C11: =B11*6 -> 24 | D11: =IFERROR(__xludf.DUMMYFUNCTION("IFERROR(IF(VLOOKUP(A11, 'Sprint 3 Backlog'!A:I, 9, FALSE)="""", 0, COUNTA(SPLIT(VLOOKUP(A11, 'Sprint 3 Backlog'!A:I, 9, FALSE), "",""))), 0) "),2) -> 2 | E11: =IFERROR(__xludf.DUMMYFUNCTION("""COMPUTED_VALUE"""),4) -> 4 | F11: =E11-C11 -> -20 | G11: =COUNTIFS('Registro de Incidentes'!A:A,A11,'Registro de Incidentes'!C:C,TRUE) -> 0 | H11: =IF(COUNTIF('Registro de Incidentes'!A:A,A11)=0,0,SUMIF('Registro de Incidentes'!A:A,A11,'Registro de Incidentes'!D:D)) -> 0 | I11: =IF(COUNTIF('Registro de Incidentes'!A:A,A11)=0,0,SUMIF('Registro de Incidentes'!A:A,A11,'Registro de Incidentes'!E:E)) -> 0
A12: {=INDEX('Sprint 3 Backlog'!A:A,ROW(A12))} -> 11 | B12: 3 | C12: =B12*6 -> 18 | D12: =IFERROR(__xludf.DUMMYFUNCTION("IFERROR(IF(VLOOKUP(A12, 'Sprint 3 Backlog'!A:I, 9, FALSE)="""", 0, COUNTA(SPLIT(VLOOKUP(A12, 'Sprint 3 Backlog'!A:I, 9, FALSE), "",""))), 0) "),1) -> 1 | E12: =IFERROR(__xludf.DUMMYFUNCTION("""COMPUTED_VALUE"""),4.1) -> 4.1 | F12: =E12-C12 -> -13.9 | G12: =COUNTIFS('Registro de Incidentes'!A:A,A12,'Registro de Incidentes'!C:C,TRUE) -> 0 | H12: =IF(COUNTIF('Registro de Incidentes'!A:A,A12)=0,0,SUMIF('Registro de Incidentes'!A:A,A12,'Registro de Incidentes'!D:D)) -> 0 | I12: =IF(COUNTIF('Registro de Incidentes'!A:A,A12)=0,0,SUMIF('Registro de Incidentes'!A:A,A12,'Registro de Incidentes'!E:E)) -> 0
A13: {=INDEX('Sprint 3 Backlog'!A:A,ROW(A13))} -> 12 | B13: 2 | C13: =B13*6 -> 12 | D13: =IFERROR(__xludf.DUMMYFUNCTION("IFERROR(IF(VLOOKUP(A13, 'Sprint 3 Backlog'!A:I, 9, FALSE)="""", 0, COUNTA(SPLIT(VLOOKUP(A13, 'Sprint 3 Backlog'!A:I, 9, FALSE), "",""))), 0) "),1) -> 1 | E13: =IFERROR(__xludf.DUMMYFUNCTION("""COMPUTED_VALUE"""),3) -> 3 | F13: =E13-C13 -> -9 | G13: =COUNTIFS('Registro de Incidentes'!A:A,A13,'Registro de Incidentes'!C:C,TRUE) -> 0 | H13: =IF(COUNTIF('Registro de Incidentes'!A:A,A13)=0,0,SUMIF('Registro de Incidentes'!A:A,A13,'Registro de Incidentes'!D:D)) -> 0 | I13: =IF(COUNTIF('Registro de Incidentes'!A:A,A13)=0,0,SUMIF('Registro de Incidentes'!A:A,A13,'Registro de Incidentes'!E:E)) -> 0
A14: {=INDEX('Sprint 3 Backlog'!A:A,ROW(A14))} -> 13 | B14: 8 | C14: =B14*6 -> 48 | D14: =IFERROR(__xludf.DUMMYFUNCTION("IFERROR(IF(VLOOKUP(A14, 'Sprint 3 Backlog'!A:I, 9, FALSE)="""", 0, COUNTA(SPLIT(VLOOKUP(A14, 'Sprint 3 Backlog'!A:I, 9, FALSE), "",""))), 0) "),2) -> 2 | E14: =IFERROR(__xludf.DUMMYFUNCTION("""COMPUTED_VALUE"""),9) -> 9 | F14: =E14-C14 -> -39 | G14: =COUNTIFS('Registro de Incidentes'!A:A,A14,'Registro de Incidentes'!C:C,TRUE) -> 0 | H14: =IF(COUNTIF('Registro de Incidentes'!A:A,A14)=0,0,SUMIF('Registro de Incidentes'!A:A,A14,'Registro de Incidentes'!D:D)) -> 0 | I14: =IF(COUNTIF('Registro de Incidentes'!A:A,A14)=0,0,SUMIF('Registro de Incidentes'!A:A,A14,'Registro de Incidentes'!E:E)) -> 0
A15: {=INDEX('Sprint 3 Backlog'!A:A,ROW(A15))} -> 801 | B15: 0 | C15: =B15*6 -> 0 | D15: =IFERROR(__xludf.DUMMYFUNCTION("IFERROR(IF(VLOOKUP(A15, 'Sprint 3 Backlog'!A:I, 9, FALSE)="""", 0, COUNTA(SPLIT(VLOOKUP(A15, 'Sprint 3 Backlog'!A:I, 9, FALSE), "",""))), 0) "),1) -> 1 | E15: =IFERROR(__xludf.DUMMYFUNCTION("""COMPUTED_VALUE"""),4) -> 4 | F15: =E15-C15 -> 4 | G15: =COUNTIFS('Registro de Incidentes'!A:A,A15,'Registro de Incidentes'!C:C,TRUE) -> 0 | H15: =IF(COUNTIF('Registro de Incidentes'!A:A,A15)=0,0,SUMIF('Registro de Incidentes'!A:A,A15,'Registro de Incidentes'!D:D)) -> 0 | I15: =IF(COUNTIF('Registro de Incidentes'!A:A,A15)=0,0,SUMIF('Registro de Incidentes'!A:A,A15,'Registro de Incidentes'!E:E)) -> 0
A16: {=INDEX('Sprint 3 Backlog'!A:A,ROW(A16))} -> 802 | B16: 0 | C16: =B16*6 -> 0 | D16: =IFERROR(__xludf.DUMMYFUNCTION("IFERROR(IF(VLOOKUP(A16, 'Sprint 3 Backlog'!A:I, 9, FALSE)="""", 0, COUNTA(SPLIT(VLOOKUP(A16, 'Sprint 3 Backlog'!A:I, 9, FALSE), "",""))), 0) "),2) -> 2 | E16: =IFERROR(__xludf.DUMMYFUNCTION("""COMPUTED_VALUE"""),0) -> 0 | F16: =E16-C16 -> 0 | G16: =COUNTIFS('Registro de Incidentes'!A:A,A16,'Registro de Incidentes'!C:C,TRUE) -> 0 | H16: =IF(COUNTIF('Registro de Incidentes'!A:A,A16)=0,0,SUMIF('Registro de Incidentes'!A:A,A16,'Registro de Incidentes'!D:D)) -> 0 | I16: =IF(COUNTIF('Registro de Incidentes'!A:A,A16)=0,0,SUMIF('Registro de Incidentes'!A:A,A16,'Registro de Incidentes'!E:E)) -> 0
A17: {=INDEX('Sprint 3 Backlog'!A:A,ROW(A17))} -> 803 | B17: 0 | C17: =B17*6 -> 0 | D17: =IFERROR(__xludf.DUMMYFUNCTION("IFERROR(IF(VLOOKUP(A17, 'Sprint 3 Backlog'!A:I, 9, FALSE)="""", 0, COUNTA(SPLIT(VLOOKUP(A17, 'Sprint 3 Backlog'!A:I, 9, FALSE), "",""))), 0) "),0) -> 0 | E17: =IFERROR(__xludf.DUMMYFUNCTION("""COMPUTED_VALUE"""),0) -> 0 | F17: =E17-C17 -> 0 | G17: =COUNTIFS('Registro de Incidentes'!A:A,A17,'Registro de Incidentes'!C:C,TRUE) -> 0 | H17: =IF(COUNTIF('Registro de Incidentes'!A:A,A17)=0,0,SUMIF('Registro de Incidentes'!A:A,A17,'Registro de Incidentes'!D:D)) -> 0 | I17: =IF(COUNTIF('Registro de Incidentes'!A:A,A17)=0,0,SUMIF('Registro de Incidentes'!A:A,A17,'Registro de Incidentes'!E:E)) -> 0
A18: {=INDEX('Sprint 3 Backlog'!A:A,ROW(A18))} -> 804 | B18: 0 | C18: =B18*6 -> 0 | D18: =IFERROR(__xludf.DUMMYFUNCTION("IFERROR(IF(VLOOKUP(A18, 'Sprint 3 Backlog'!A:I, 9, FALSE)="""", 0, COUNTA(SPLIT(VLOOKUP(A18, 'Sprint 3 Backlog'!A:I, 9, FALSE), "",""))), 0) "),3) -> 3 | E18: =IFERROR(__xludf.DUMMYFUNCTION("""COMPUTED_VALUE"""),1) -> 1 | F18: =E18-C18 -> 1 | G18: =COUNTIFS('Registro de Incidentes'!A:A,A18,'Registro de Incidentes'!C:C,TRUE) -> 0 | H18: =IF(COUNTIF('Registro de Incidentes'!A:A,A18)=0,0,SUMIF('Registro de Incidentes'!A:A,A18,'Registro de Incidentes'!D:D)) -> 0 | I18: =IF(COUNTIF('Registro de Incidentes'!A:A,A18)=0,0,SUMIF('Registro de Incidentes'!A:A,A18,'Registro de Incidentes'!E:E)) -> 0
A19: {=INDEX('Sprint 3 Backlog'!A:A,ROW(A19))} -> 805 | B19: 0 | C19: =B19*6 -> 0 | D19: =IFERROR(__xludf.DUMMYFUNCTION("IFERROR(IF(VLOOKUP(A19, 'Sprint 3 Backlog'!A:I, 9, FALSE)="""", 0, COUNTA(SPLIT(VLOOKUP(A19, 'Sprint 3 Backlog'!A:I, 9, FALSE), "",""))), 0) "),0) -> 0 | E19: =IFERROR(__xludf.DUMMYFUNCTION("""COMPUTED_VALUE"""),1) -> 1 | F19: =E19-C19 -> 1 | G19: =COUNTIFS('Registro de Incidentes'!A:A,A19,'Registro de Incidentes'!C:C,TRUE) -> 0 | H19: =IF(COUNTIF('Registro de Incidentes'!A:A,A19)=0,0,SUMIF('Registro de Incidentes'!A:A,A19,'Registro de Incidentes'!D:D)) -> 0 | I19: =IF(COUNTIF('Registro de Incidentes'!A:A,A19)=0,0,SUMIF('Registro de Incidentes'!A:A,A19,'Registro de Incidentes'!E:E)) -> 0
A20: {=INDEX('Sprint 3 Backlog'!A:A,ROW(A20))} -> 806 | B20: 0 | C20: =B20*6 -> 0 | D20: =IFERROR(__xludf.DUMMYFUNCTION("IFERROR(IF(VLOOKUP(A20, 'Sprint 3 Backlog'!A:I, 9, FALSE)="""", 0, COUNTA(SPLIT(VLOOKUP(A20, 'Sprint 3 Backlog'!A:I, 9, FALSE), "",""))), 0) "),2) -> 2 | E20: =IFERROR(__xludf.DUMMYFUNCTION("""COMPUTED_VALUE"""),0) -> 0 | F20: =E20-C20 -> 0 | G20: =COUNTIFS('Registro de Incidentes'!A:A,A20,'Registro de Incidentes'!C:C,TRUE) -> 0 | H20: =IF(COUNTIF('Registro de Incidentes'!A:A,A20)=0,0,SUMIF('Registro de Incidentes'!A:A,A20,'Registro de Incidentes'!D:D)) -> 0 | I20: =IF(COUNTIF('Registro de Incidentes'!A:A,A20)=0,0,SUMIF('Registro de Incidentes'!A:A,A20,'Registro de Incidentes'!E:E)) -> 0
A21: {=INDEX('Sprint 3 Backlog'!A:A,ROW(A21))} -> 807 | B21: 0 | C21: =B21*6 -> 0 | D21: =IFERROR(__xludf.DUMMYFUNCTION("IFERROR(IF(VLOOKUP(A21, 'Sprint 3 Backlog'!A:I, 9, FALSE)="""", 0, COUNTA(SPLIT(VLOOKUP(A21, 'Sprint 3 Backlog'!A:I, 9, FALSE), "",""))), 0) "),1) -> 1 | E21: =IFERROR(__xludf.DUMMYFUNCTION("""COMPUTED_VALUE"""),0) -> 0 | F21: =E21-C21 -> 0 | G21: =COUNTIFS('Registro de Incidentes'!A:A,A21,'Registro de Incidentes'!C:C,TRUE) -> 0 | H21: =IF(COUNTIF('Registro de Incidentes'!A:A,A21)=0,0,SUMIF('Registro de Incidentes'!A:A,A21,'Registro de Incidentes'!D:D)) -> 0 | I21: =IF(COUNTIF('Registro de Incidentes'!A:A,A21)=0,0,SUMIF('Registro de Incidentes'!A:A,A21,'Registro de Incidentes'!E:E)) -> 0
A22: {=INDEX('Sprint 3 Backlog'!A:A,ROW(A22))} -> 808 | B22: 0 | C22: =B22*6 -> 0 | D22: =IFERROR(__xludf.DUMMYFUNCTION("IFERROR(IF(VLOOKUP(A22, 'Sprint 3 Backlog'!A:I, 9, FALSE)="""", 0, COUNTA(SPLIT(VLOOKUP(A22, 'Sprint 3 Backlog'!A:I, 9, FALSE), "",""))), 0) "),2) -> 2 | E22: =IFERROR(__xludf.DUMMYFUNCTION("""COMPUTED_VALUE"""),0) -> 0 | F22: =E22-C22 -> 0 | G22: =COUNTIFS('Registro de Incidentes'!A:A,A22,'Registro de Incidentes'!C:C,TRUE) -> 0 | H22: =IF(COUNTIF('Registro de Incidentes'!A:A,A22)=0,0,SUMIF('Registro de Incidentes'!A:A,A22,'Registro de Incidentes'!D:D)) -> 0 | I22: =IF(COUNTIF('Registro de Incidentes'!A:A,A22)=0,0,SUMIF('Registro de Incidentes'!A:A,A22,'Registro de Incidentes'!E:E)) -> 0
A23: {=INDEX('Sprint 3 Backlog'!A:A,ROW(A23))} -> 809 | B23: 0 | C23: =B23*6 -> 0 | D23: =IFERROR(__xludf.DUMMYFUNCTION("IFERROR(IF(VLOOKUP(A23, 'Sprint 3 Backlog'!A:I, 9, FALSE)="""", 0, COUNTA(SPLIT(VLOOKUP(A23, 'Sprint 3 Backlog'!A:I, 9, FALSE), "",""))), 0) "),1) -> 1 | E23: =IFERROR(__xludf.DUMMYFUNCTION("""COMPUTED_VALUE"""),0) -> 0 | F23: =E23-C23 -> 0 | G23: =COUNTIFS('Registro de Incidentes'!A:A,A23,'Registro de Incidentes'!C:C,TRUE) -> 0 | H23: =IF(COUNTIF('Registro de Incidentes'!A:A,A23)=0,0,SUMIF('Registro de Incidentes'!A:A,A23,'Registro de Incidentes'!D:D)) -> 0 | I23: =IF(COUNTIF('Registro de Incidentes'!A:A,A23)=0,0,SUMIF('Registro de Incidentes'!A:A,A23,'Registro de Incidentes'!E:E)) -> 0
